Workbook
Name _DCFData: _DCFBegin:_DCFSaleYear
Name _DCFData: _DCFBegin:_DCFSaleYear
Name _DCFData: _DCFBegin:_DCFSaleYear
Name _DCFData: _DCFBegin:_DCFSaleYear
Name _DCFData: _DCFBegin:_DCFSaleYear
Name _DCFData: _DCFBegin:_DCFSaleYear
Name _DCFMonths: _DCFFirstMonth:_DCFLastMonth
Name _DCFMonths: _DCFFirstMonth:_DCFLastMonth
Name _DCFMonths: _DCFFirstMonth:_DCFLastMonth
Name _DCFMonths: _DCFFirstMonth:_DCFLastMonth
Name _DCFMonths: _DCFFirstMonth:_DCFLastMonth
Name _DCFMonths: _DCFFirstMonth:_DCFLastMonth
Name _Level_Values: [2]Enumerations!$7:$7
Name _WF_Period_lookup: '1-Yr Waterfall'!$B$358:$E$360
Name _WF_Period_lookup: '3-Yr Waterfall'!$B$358:$E$360
Name _WF_Period_lookup: '4-Yr Waterfall'!$B$358:$E$360
Name _WF_Periodicity: '1-Yr Waterfall'!$R$9
Name _WF_Periodicity: '3-Yr Waterfall'!$R$9
Name _WF_Periodicity: '4-Yr Waterfall'!$R$9
Name _WF_Remainder_GP: '1-Yr Waterfall'!$J$15
Name _WF_Remainder_GP: '3-Yr Waterfall'!$J$15
Name _WF_Remainder_GP: '4-Yr Waterfall'!$J$15
Name _WF_Remainder_LP: '1-Yr Waterfall'!$J$13
Name _WF_Remainder_LP: '3-Yr Waterfall'!$J$13
Name _WF_Remainder_LP: '4-Yr Waterfall'!$J$13
Name _WF_Tier1_GP: '1-Yr Waterfall'!$E$15
Name _WF_Tier1_GP: '3-Yr Waterfall'!$E$15
Name _WF_Tier1_GP: '4-Yr Waterfall'!$E$15
Name _WF_Tier1_LP: '1-Yr Waterfall'!$E$13
Name _WF_Tier1_LP: '3-Yr Waterfall'!$E$13
Name _WF_Tier1_LP: '4-Yr Waterfall'!$E$13
Name _WF_Tier1_Rate: '1-Yr Waterfall'!$D$10
Name _WF_Tier1_Rate: '3-Yr Waterfall'!$D$10
Name _WF_Tier1_Rate: '4-Yr Waterfall'!$D$10
Name _WF_Tier2_GP: '1-Yr Waterfall'!$G$15
Name _WF_Tier2_GP: '3-Yr Waterfall'!$G$15
Name _WF_Tier2_GP: '4-Yr Waterfall'!$G$15
Name _WF_Tier2_LP: '1-Yr Waterfall'!$G$13
Name _WF_Tier2_LP: '3-Yr Waterfall'!$G$13
Name _WF_Tier2_LP: '4-Yr Waterfall'!$G$13
Name _WF_Tier2_Rate: '1-Yr Waterfall'!$F$10
Name _WF_Tier2_Rate: '3-Yr Waterfall'!$F$10
Name _WF_Tier2_Rate: '4-Yr Waterfall'!$F$10
Name _WF_Tier3_GP: '1-Yr Waterfall'!$I$15
Name _WF_Tier3_GP: '3-Yr Waterfall'!$I$15
Name _WF_Tier3_GP: '4-Yr Waterfall'!$I$15
Name _WF_Tier3_LP: '1-Yr Waterfall'!$I$13
Name _WF_Tier3_LP: '3-Yr Waterfall'!$I$13
Name _WF_Tier3_LP: '4-Yr Waterfall'!$I$13
Name _WF_Tier3_Rate: '1-Yr Waterfall'!$H$10
Name _WF_Tier3_Rate: '3-Yr Waterfall'!$H$10
Name _WF_Tier3_Rate: '4-Yr Waterfall'!$H$10
Name A12..F975_: '[3]PH(1)'!#REF!
Name aaa: #REF!
Name aaaa: #REF!
Name aaaaa: #REF!
Name aaaaaaaaaaaa: [4]COMPEST!#REF!
Name Acres: 'Executive Summary'!$E$9
Name AE: #REF!
Name Amortization_Period___Years: "Loan1AmortYrs"

Sheet Executive Summary
B1: =$E$5& " EXECUTIVE SUMMARY" -> VERVE Chapel Hill EXECUTIVE SUMMARY
B4: PROJECT SUMMARY | G4: RETURN METRICS
B5: Project Name | E5: VERVE Chapel Hill | G5: Total Project Budget | K5: Stab. Year | L5: =C48 -> 2.3895397e+08
B6: Address | E6: 600 Martin Luther King Blvd, Chapel Hill, NC 27516 | G6: ="Yr. "&K6&" Return on Cost" -> Yr. 2 Return on Cost | K6: 2 | L6: =OFFSET('Cash Flow'!$F$46,0,K6-1) -> 0.083265659
B7: Land Acquisition | E7: 46753 | G7: Development Spread | L7: =((L6*100)-(J15*100))*100 -> 317.65659
B8: Investment Committee Approval Date | E8: 46082
B9: Land Size (Acres) | E9: =+Development!H19 -> 7.7800046
B10: Number of Stories | E10: 7 Stories | G10: Sale Method | L10: Cap Sale Yr+1
B11: Type of Build | E11: Podium | G11: Cost of Sale | L11: 0.0075
B12: Units | E12: =+Assumptions!D6 -> 461.33501
B13: Beds | E13: =+Assumptions!M22 -> 1241.4577 | G13: ="Holding Period after Delivery ("&TEXT($C$72,"M/d/YY")&")" -> Holding Period after Delivery (8/1/30) | J13: 1 | K13: 3 | L13: 4
B14: Beds/Unit | E14: =Beds/Units -> 2.6910112 | G14: Sale Date | J14: =+'1-Yr Waterfall'!R12 -> 48060 | K14: =+'3-Yr Waterfall'!R12 -> 48791 | L14: =+'4-Yr Waterfall'!R12 -> 49156
B15: Total Parking Spaces | E15: =+ResiParkingSpaces+Assumptions!D39 -> 624 | G15: Exit Cap Rate | J15: 0.0515 | K15: 0.0535 | L15: 0.0545
B16: Residential Parking Spaces | E16: =+Assumptions!D21 -> 624 | G16: Levered IRR | J16: ='Returns Exhibit'!F9 -> 0.36822192 | K16: ='Returns Exhibit'!F21 -> 0.29012798 | L16: ='Returns Exhibit'!F33 -> 0.26983899
B17: % Units Parked | E17: =E16/Units -> 1.3525962 | G17: Levered Multiple | J17: ='Returns Exhibit'!G9 -> 2.7806285 | K17: ='Returns Exhibit'!G21 -> 3.0807703 | L17: ='Returns Exhibit'!G33 -> 3.2530537
B18: % Beds Parked | E18: =E16/Beds -> 0.50263492
B19: Net Residential SF | E19: =+Assumptions!U22 -> 428715
B20: Gross Residential SF | E20: =+Development!H11 -> 502832
B21: Commercial SF | E21: =+Assumptions!I45 -> 1824
B22: Amenity & Leasing SF | E22: =+Development!H12 -> 20325
B23: Total SF (excluding Parking) | E23: =SUM(D20:E22) -> 524981
B24: Parking SF | E24: =+Development!H14 -> 232842
B26: PROJECT BUDGET | G26: UNIT RENT ASSUMPTIONS | O26: Units
K27: Rent/ | L27: Rent/
B28: Uses | C28: Total | D28: $/Bed | E28: $/Unit | G28: Unit Type | H28: # of Beds | I28: % of Beds | J28: SF/Unit | K28: Bed/Month | L28: RSF/Month | O28: =IFERROR(IF(OFFSET(O28,-1,0)+1>$O$35,"",OFFSET(O28,-1,0)+1),"") -> 1
B29: Acquisition Costs | C29: =+'Development Summary'!I14 -> 26063675 | D29: =IFERROR($C29/Beds,0) -> 20994.412 | E29: =IFERROR($C29/Units,0) -> 56496.2 | G29: =IFERROR(OFFSET(Assumptions!$H$24,$O28,0),"") -> STUDIO | H29: =IFERROR(OFFSET(Assumptions!$M$24,$O28,0),"") -> 28.509467 | I29: =+IFERROR(H29/$H$36,"") -> 0.022964509 | J29: =IFERROR(OFFSET(Assumptions!$I$24,$O28,0),"") -> 414 | K29: =IFERROR(OFFSET(Assumptions!$R$24,$O28,0),"") -> 1726.8663 | L29: =IFERROR(OFFSET(Assumptions!$T$24,$O28,0),"") -> 4.1711746 | O29: =IFERROR(IF(OFFSET(O29,-1,0)+1>$O$35,"",OFFSET(O29,-1,0)+1),"") -> 2
B30: Hard Costs | C30: =+'Development Summary'!I20 -> 1.6970318e+08 | D30: =IFERROR($C30/Beds,0) -> 136696.71 | E30: =IFERROR($C30/Units,0) -> 367852.37 | G30: =IFERROR(OFFSET(Assumptions!$H$24,$O29,0),"") -> 1BR/1BA | H30: =IFERROR(OFFSET(Assumptions!$M$24,$O29,0),"") -> 69.977783 | I30: =+IFERROR(H30/$H$36,"") -> 0.056367432 | J30: =IFERROR(OFFSET(Assumptions!$I$24,$O29,0),"") -> 500 | K30: =IFERROR(OFFSET(Assumptions!$R$24,$O29,0),"") -> 2100.1339 | L30: =IFERROR(OFFSET(Assumptions!$T$24,$O29,0),"") -> 4.2002678 | O30: =IFERROR(IF(OFFSET(O30,-1,0)+1>$O$35,"",OFFSET(O30,-1,0)+1),"") -> 3
B31: Architectural / Engineering / Design | C31: =+'Development Summary'!I22 -> 4551801.1 | D31: =IFERROR($C31/Beds,0) -> 3666.4971 | E31: =IFERROR($C31/Units,0) -> 9866.5849 | G31: =IFERROR(OFFSET(Assumptions!$H$24,$O30,0),"") -> 2BR/2BA | H31: =IFERROR(OFFSET(Assumptions!$M$24,$O30,0),"") -> 233.25928 | I31: =+IFERROR(H31/$H$36,"") -> 0.18789144 | J31: =IFERROR(OFFSET(Assumptions!$I$24,$O30,0),"") -> 750 | K31: =IFERROR(OFFSET(Assumptions!$R$24,$O30,0),"") -> 1722.8211 | L31: =IFERROR(OFFSET(Assumptions!$T$24,$O30,0),"") -> 4.5941895 | O31: =IFERROR(IF(OFFSET(O31,-1,0)+1>$O$35,"",OFFSET(O31,-1,0)+1),"") -> 4
B32: Diligence Consultants | C32: =+'Development Summary'!I23 -> 538617.69 | D32: =IFERROR($C32/Beds,0) -> 433.85907 | E32: =IFERROR($C32/Units,0) -> 1167.5196 | G32: =IFERROR(OFFSET(Assumptions!$H$24,$O31,0),"") -> 3BR/3BA | H32: =IFERROR(OFFSET(Assumptions!$M$24,$O31,0),"") -> 225.48397 | I32: =+IFERROR(H32/$H$36,"") -> 0.18162839 | J32: =IFERROR(OFFSET(Assumptions!$I$24,$O31,0),"") -> 1050 | K32: =IFERROR(OFFSET(Assumptions!$R$24,$O31,0),"") -> 1684.7353 | L32: =IFERROR(OFFSET(Assumptions!$T$24,$O31,0),"") -> 4.8135295 | O32: =IFERROR(IF(OFFSET(O32,-1,0)+1>$O$35,"",OFFSET(O32,-1,0)+1),"") -> 5
B33: Permit / City Fees | C33: =+'Development Summary'!I24 -> 1321042.2 | D33: =IFERROR($C33/Beds,0) -> 1064.1057 | E33: =IFERROR($C33/Units,0) -> 2863.5204 | G33: =IFERROR(OFFSET(Assumptions!$H$24,$O32,0),"") -> 4BR/4BA | H33: =IFERROR(OFFSET(Assumptions!$M$24,$O32,0),"") -> 684.22721 | I33: =+IFERROR(H33/$H$36,"") -> 0.55114823 | J33: =IFERROR(OFFSET(Assumptions!$I$24,$O32,0),"") -> 1260 | K33: =IFERROR(OFFSET(Assumptions!$R$24,$O32,0),"") -> 1693.7269 | L33: =IFERROR(OFFSET(Assumptions!$T$24,$O32,0),"") -> 5.3769106 | O33: =IFERROR(IF(OFFSET(O33,-1,0)+1>$O$35,"",OFFSET(O33,-1,0)+1),"")
B34: Legal / Professional / Admin Services | C34: =+'Development Summary'!I25 -> 1290000 | D34: =IFERROR($C34/Beds,0) -> 1039.101 | E34: =IFERROR($C34/Units,0) -> 2796.2326 | G34: =IFERROR(OFFSET(Assumptions!$H$24,$O33,0),"") | H34: =IFERROR(OFFSET(Assumptions!$M$24,$O33,0),"") | I34: =+IFERROR(H34/$H$36,"") | J34: =IFERROR(OFFSET(Assumptions!$I$24,$O33,0),"") | K34: =IFERROR(OFFSET(Assumptions!$R$24,$O33,0),"") | L34: =IFERROR(OFFSET(Assumptions!$T$24,$O33,0),"") | O34: =IFERROR(IF(OFFSET(O34,-1,0)+1>$O$35,"",OFFSET(O34,-1,0)+1),"")
B35: Leasing & Operations | C35: =+'Development Summary'!I26 -> 2422981.3 | D35: =IFERROR($C35/Beds,0) -> 1951.7228 | E35: =IFERROR($C35/Units,0) -> 5252.108 | O35: =+Assumptions!F37 -> 5
B36: FF&E | C36: =+'Development Summary'!I27 -> 6448298.9 | D36: =IFERROR($C36/Beds,0) -> 5194.135 | E36: =IFERROR($C36/Units,0) -> 13977.476 | G36: Total Residential | H36: =SUM(H29:H34) -> 1241.4577 | I36: =+H36/$H$36 -> 1 | J36: =Assumptions!I22 -> 929.29213 | K36: =SUMPRODUCT(K29:K34,$H$29:$H$34)/$H$36 -> 1721.2294 | L36: =Assumptions!S22/Assumptions!I22 -> 4.9842752
B37: Taxes and Insurance | C37: =+'Development Summary'!I28 -> 3006319.7 | D37: =IFERROR($C37/Beds,0) -> 2421.6046 | E37: =IFERROR($C37/Units,0) -> 6516.5652
B38: Construction Financing Costs | C38: =+'Development Summary'!I29 -> 9958874.8 | D38: =IFERROR($C38/Beds,0) -> 8021.9203 | E38: =IFERROR($C38/Units,0) -> 21587.078 | G38: Unit Type | J38: RSF/Unit | K38: Rent/Year | L38: RSF/Year | O38: =IFERROR(IF(OFFSET(O38,-1,0)+1>$O$41,"",OFFSET(O38,-1,0)+1),"") -> 1
B39: Soft Cost Contingency | C39: =+'Development Summary'!I30 -> 1064579.8 | D39: =IFERROR($C39/Beds,0) -> 857.52401 | E39: =IFERROR($C39/Units,0) -> 2307.6068 | G39: =IF(Assumptions!$G43=0,"",Assumptions!$G43) -> Retail | J39: =IF(Assumptions!$I43=0,"",Assumptions!$I43) -> 1824 | K39: =IF(Assumptions!$N43=0,"",Assumptions!$N43) -> 63780.29 | L39: =IF(Assumptions!$L43=0,"",Assumptions!$L43) -> 32 | O39: =IFERROR(IF(OFFSET(O39,-1,0)+1>$O$41,"",OFFSET(O39,-1,0)+1),"")
B40: Development Fee | C40: =+'Development Summary'!I31 -> 9190537.3 | D40: =IFERROR($C40/Beds,0) -> 7403.0209 | E40: =IFERROR($C40/Units,0) -> 19921.612 | G40: =IF(Assumptions!$G44=0,"",Assumptions!$G44) | J40: =IF(Assumptions!$I44=0,"",Assumptions!$I44) | K40: =IF(Assumptions!$N44=0,"",Assumptions!$N44) | L40: =IF(Assumptions!$L44=0,"",Assumptions!$L44) | O40: =IFERROR(IF(OFFSET(O40,-1,0)+1>$O$41,"",OFFSET(O40,-1,0)+1),"")
B41: Construction Management Fee | C41: =+'Development Summary'!I32 -> 3394063.6 | D41: =IFERROR($C41/Beds,0) -> 2733.9341 | E41: =IFERROR($C41/Units,0) -> 7357.0474 | G41: Total Commercial | J41: =Assumptions!I45 -> 1824 | K41: =Assumptions!N45 -> 63780.29 | L41: =Assumptions!L45 -> 32 | O41: =+Assumptions!F45 -> 1
B42: Total Uses | C42: =+'Development Summary'!I36 -> 2.3895397e+08 | D42: =IFERROR($C42/Beds,0) -> 192478.54 | E42: =IFERROR($C42/Units,0) -> 517961.92
G43: ="OPERATING BUDGET (Yr. "&K44&")" -> OPERATING BUDGET (Yr. 2)
...

Sheet Development Summary
D1: =+'Executive Summary'!E5 & " DEVELOPMENT COST SUMMARY" -> VERVE Chapel Hill DEVELOPMENT COST SUMMARY
E5: Development Costs | L5: Project Size
L6: Units | N6: Beds | P6: Gross SF | R6: Net SF
A7: Filters/Lookups | L7: =Development!$H$9 -> 461.33501 | N7: =Development!$H$10 -> 1241.4577 | P7: =Development!$H$15 -> 757823 | R7: =Development!$H$16 -> 428715
A8: CODE | B8: # | C8: Asset | E8: Line Items | G8: % of Total | I8: $ Amount | L8: $/Unit | N8: $/Bed | P8: $/GSF | R8: $/NRSF
A9: =B9&" - "&E9 -> # - | B9: =OFFSET(B9,-1,0) -> # | C9: =OFFSET(C9,-1,0) -> Asset
A10: =B10&" - "&E10 -> # - Land Costs | B10: =OFFSET(B10,-1,0) -> # | C10: =OFFSET(C10,-1,0) -> Asset | E10: =+Development!E35 -> Land Costs | G10: =I10/$I$36 -> 0.10708129 | I10: =+Development!G40 -> 25587500 | L10: =IFERROR($I10/L$7,0) -> 55464.032 | N10: =IFERROR($I10/N$7,0) -> 20610.851 | P10: =IFERROR($I10/P$7,0) -> 33.764481 | R10: =IFERROR($I10/R$7,0) -> 59.684172
A11: =B11&" - "&E11 -> # - Closing Costs | B11: =OFFSET(B11,-1,0) -> # | C11: =OFFSET(C11,-1,0) -> Asset | E11: =+Development!E42 -> Closing Costs | G11: =I11/$I$36 -> 0.0009465212 | I11: =+Development!G49 -> 226175 | L11: =IFERROR($I11/L$7,0) -> 490.26194 | N11: =IFERROR($I11/N$7,0) -> 182.18502 | P11: =IFERROR($I11/P$7,0) -> 0.2984536 | R11: =IFERROR($I11/R$7,0) -> 0.52756493
A12: =B12&" - "&E12 -> # - Total Miscellaneous | B12: =OFFSET(B12,-1,0) -> # | C12: =OFFSET(C12,-1,0) -> Asset | E12: =+Development!E56 -> Total Miscellaneous | G12: =I12/$I$36 -> 0.0010462266 | I12: =+Development!G56 -> 250000 | L12: =IFERROR($I12/L$7,0) -> 541.90554 | N12: =IFERROR($I12/N$7,0) -> 201.37617 | P12: =IFERROR($I12/P$7,0) -> 0.32989234 | R12: =IFERROR($I12/R$7,0) -> 0.58313798
A13: =B13&" - "&E13 -> # - | B13: =OFFSET(B13,-1,0) -> # | C13: =OFFSET(C13,-1,0) -> Asset
A14: =B14&" - "&E14 -> # - Total Acquisition Costs | B14: =OFFSET(B14,-1,0) -> # | C14: =OFFSET(C14,-1,0) -> Asset | E14: Total Acquisition Costs | G14: =I14/$I$36 -> 0.10907404 | I14: =+SUM(I10:I13) -> 26063675 | L14: =IFERROR($I14/L$7,0) -> 56496.2 | N14: =IFERROR($I14/N$7,0) -> 20994.412 | P14: =IFERROR($I14/P$7,0) -> 34.392827 | R14: =IFERROR($I14/R$7,0) -> 60.794875
A15: =B15&" - "&E15 -> # - | B15: =OFFSET(B15,-1,0) -> # | C15: =OFFSET(C15,-1,0) -> Asset
A16: =B16&" - "&E16 -> # - Site Work | B16: =OFFSET(B16,-1,0) -> # | C16: =OFFSET(C16,-1,0) -> Asset | E16: =+Development!E62 -> Site Work | G16: =I16/$I$36 -> 0.0032433025 | I16: =+Development!G69 -> 775000 | L16: =IFERROR($I16/L$7,0) -> 1679.9072 | N16: =IFERROR($I16/N$7,0) -> 624.26613 | P16: =IFERROR($I16/P$7,0) -> 1.0226662 | R16: =IFERROR($I16/R$7,0) -> 1.8077277
A17: =B17&" - "&E17 -> # - Construction Costs | B17: =OFFSET(B17,-1,0) -> # | C17: =OFFSET(C17,-1,0) -> Asset | E17: =+Development!E71 -> Construction Costs | G17: =I17/$I$36 -> 0.67312995 | I17: =+Development!G81 -> 1.6084708e+08 | L17: =IFERROR($I17/L$7,0) -> 348655.69 | N17: =IFERROR($I17/N$7,0) -> 129563.07 | P17: =IFERROR($I17/P$7,0) -> 212.24887 | R17: =IFERROR($I17/R$7,0) -> 375.18416
A18: =B18&" - "&E18 -> # - Hard Cost Contingency | B18: =OFFSET(B18,-1,0) -> # | C18: =OFFSET(C18,-1,0) -> Asset | E18: =+Development!E83 -> Hard Cost Contingency | G18: =I18/$I$36 -> 0.033818663 | I18: =+Development!G87 -> 8081103.8 | L18: =IFERROR($I18/L$7,0) -> 17516.78 | N18: =IFERROR($I18/N$7,0) -> 6509.367 | P18: =IFERROR($I18/P$7,0) -> 10.663577 | R18: =IFERROR($I18/R$7,0) -> 18.849594
A19: =B19&" - "&E19 -> # - | B19: =OFFSET(B19,-1,0) -> # | C19: =OFFSET(C19,-1,0) -> Asset
A20: =B20&" - "&E20 -> # - Total Hard Costs | B20: =OFFSET(B20,-1,0) -> # | C20: =OFFSET(C20,-1,0) -> Asset | E20: Total Hard Costs | G20: =I20/$I$36 -> 0.71019192 | I20: =+SUM(I16:I19) -> 1.6970318e+08 | L20: =IFERROR($I20/L$7,0) -> 367852.37 | N20: =IFERROR($I20/N$7,0) -> 136696.71 | P20: =IFERROR($I20/P$7,0) -> 223.93511 | R20: =IFERROR($I20/R$7,0) -> 395.84148
A21: =B21&" - "&E21 -> # - | B21: =OFFSET(B21,-1,0) -> # | C21: =OFFSET(C21,-1,0) -> Asset
A22: =B22&" - "&E22 -> # - Architectural / Engineering / Design | B22: =OFFSET(B22,-1,0) -> # | C22: =OFFSET(C22,-1,0) -> Asset | E22: =+Development!E93 -> Architectural / Engineering / Design | G22: =I22/$I$36 -> 0.019048862 | I22: =+Development!G110 -> 4551801.1 | L22: =IFERROR($I22/L$7,0) -> 9866.5849 | N22: =IFERROR($I22/N$7,0) -> 3666.4971 | P22: =IFERROR($I22/P$7,0) -> 6.0064172 | R22: =IFERROR($I22/R$7,0) -> 10.617312
A23: =B23&" - "&E23 -> # - Diligence Consultants | B23: =OFFSET(B23,-1,0) -> # | C23: =OFFSET(C23,-1,0) -> Asset | E23: =+Development!E112 -> Diligence Consultants | G23: =I23/$I$36 -> 0.0022540646 | I23: =+Development!G123 -> 538617.69 | L23: =IFERROR($I23/L$7,0) -> 1167.5196 | N23: =IFERROR($I23/N$7,0) -> 433.85907 | P23: =IFERROR($I23/P$7,0) -> 0.71074339 | R23: =IFERROR($I23/R$7,0) -> 1.2563537
A24: =B24&" - "&E24 -> # - Permit/City Fees | B24: =OFFSET(B24,-1,0) -> # | C24: =OFFSET(C24,-1,0) -> Asset | E24: =+Development!E125 -> Permit/City Fees | G24: =I24/$I$36 -> 0.0055284381 | I24: =+Development!G146 -> 1321042.2 | L24: =IFERROR($I24/L$7,0) -> 2863.5204 | N24: =IFERROR($I24/N$7,0) -> 1064.1057 | P24: =IFERROR($I24/P$7,0) -> 1.7432068 | R24: =IFERROR($I24/R$7,0) -> 3.0813996
A25: =B25&" - "&E25 -> # - Legal / Professional / Admin Services | B25: =OFFSET(B25,-1,0) -> # | C25: =OFFSET(C25,-1,0) -> Asset | E25: =+Development!E148 -> Legal / Professional / Admin Services | G25: =I25/$I$36 -> 0.0053985293 | I25: =+Development!G161 -> 1290000 | L25: =IFERROR($I25/L$7,0) -> 2796.2326 | N25: =IFERROR($I25/N$7,0) -> 1039.101 | P25: =IFERROR($I25/P$7,0) -> 1.7022445 | R25: =IFERROR($I25/R$7,0) -> 3.008992
A26: =B26&" - "&E26 -> # - Leasing & Operations | B26: =OFFSET(B26,-1,0) -> # | C26: =OFFSET(C26,-1,0) -> Asset | E26: =+Development!E163 -> Leasing & Operations | G26: =I26/$I$36 -> 0.01013995 | I26: =+Development!G174 -> 2422981.3 | L26: =IFERROR($I26/L$7,0) -> 5252.108 | N26: =IFERROR($I26/N$7,0) -> 1951.7228 | P26: =IFERROR($I26/P$7,0) -> 3.1972919 | R26: =IFERROR($I26/R$7,0) -> 5.6517297
A27: =B27&" - "&E27 -> # - FF&E | B27: =OFFSET(B27,-1,0) -> # | C27: =OFFSET(C27,-1,0) -> Asset | E27: =+Development!E176 -> FF&E | G27: =I27/$I$36 -> 0.026985527 | I27: =+Development!G196 -> 6448298.9 | L27: =IFERROR($I27/L$7,0) -> 13977.476 | N27: =IFERROR($I27/N$7,0) -> 5194.135 | P27: =IFERROR($I27/P$7,0) -> 8.5089776 | R27: =IFERROR($I27/R$7,0) -> 15.040992
A28: =B28&" - "&E28 -> # - Taxes and Insurance | B28: =OFFSET(B28,-1,0) -> # | C28: =OFFSET(C28,-1,0) -> Asset | E28: =+Development!E198 -> Taxes and Insurance | G28: =I28/$I$36 -> 0.012581167 | I28: =+Development!G205 -> 3006319.7 | L28: =IFERROR($I28/L$7,0) -> 6516.5652 | N28: =IFERROR($I28/N$7,0) -> 2421.6046 | P28: =IFERROR($I28/P$7,0) -> 3.9670473 | R28: =IFERROR($I28/R$7,0) -> 7.0123968
A29: =B29&" - "&E29 -> # - Construction Financing Costs | B29: =OFFSET(B29,-1,0) -> # | C29: =OFFSET(C29,-1,0) -> Asset | E29: =+Development!E212 -> Construction Financing Costs | G29: =I29/$I$36 -> 0.041676959 | I29: =+Development!G225 -> 9958874.8 | L29: =IFERROR($I29/L$7,0) -> 21587.078 | N29: =IFERROR($I29/N$7,0) -> 8021.9203 | P29: =IFERROR($I29/P$7,0) -> 13.141426 | R29: =IFERROR($I29/R$7,0) -> 23.229593
A30: =B30&" - "&E30 -> # - Soft Cost Contingency | B30: =OFFSET(B30,-1,0) -> # | C30: =OFFSET(C30,-1,0) -> Asset | E30: =+Development!E227 -> Soft Cost Contingency | G30: =I30/$I$36 -> 0.0044551668 | I30: =+Development!G231 -> 1064579.8 | L30: =IFERROR($I30/L$7,0) -> 2307.6068 | N30: =IFERROR($I30/N$7,0) -> 857.52401 | P30: =IFERROR($I30/P$7,0) -> 1.4047869 | R30: =IFERROR($I30/R$7,0) -> 2.4831877
A31: =B31&" - "&E31 -> # - Development Fee | B31: =OFFSET(B31,-1,0) -> # | C31: =OFFSET(C31,-1,0) -> Asset | E31: =+Development!E234 -> Development Fee | G31: =I31/$I$36 -> 0.038461538 | I31: =+Development!G238 -> 9190537.3 | L31: =IFERROR($I31/L$7,0) -> 19921.612 | N31: =IFERROR($I31/N$7,0) -> 7403.0209 | P31: =IFERROR($I31/P$7,0) -> 12.127551 | R31: =IFERROR($I31/R$7,0) -> 21.437406
A32: =B32&" - "&E32 -> # - Construction Management Fee | B32: =OFFSET(B32,-1,0) -> # | C32: =OFFSET(C32,-1,0) -> Asset | E32: =+Development!E240 -> Construction Management Fee | G32: =I32/$I$36 -> 0.014203838 | I32: =+Development!G244 -> 3394063.6 | L32: =IFERROR($I32/L$7,0) -> 7357.0474 | N32: =IFERROR($I32/N$7,0) -> 2733.9341 | P32: =IFERROR($I32/P$7,0) -> 4.4787023 | R32: =IFERROR($I32/R$7,0) -> 7.9168296
A33: =B33&" - "&E33 -> # - | B33: =OFFSET(B33,-1,0) -> # | C33: =OFFSET(C33,-1,0) -> Asset
A34: =B34&" - "&E34 -> # - Total Soft Costs | B34: =OFFSET(B34,-1,0) -> # | C34: =OFFSET(C34,-1,0) -> Asset | E34: Total Soft Costs | G34: =I34/$I$36 -> 0.18073404 | I34: =+SUM(I22:I33) -> 43187116 | L34: =IFERROR($I34/L$7,0) -> 93613.351 | N34: =IFERROR($I34/N$7,0) -> 34787.425 | P34: =IFERROR($I34/P$7,0) -> 56.988395 | R34: =IFERROR($I34/R$7,0) -> 100.73619
A35: =B35&" - "&E35 -> # - | B35: =OFFSET(B35,-1,0) -> # | C35: =OFFSET(C35,-1,0) -> Asset
A36: =B36&" - "&#REF! -> #REF! | B36: =OFFSET(B36,-1,0) -> # | C36: =OFFSET(C36,-1,0) -> Asset | E36: TOTAL DEVELOPMENT COSTS | G36: =I36/$I$36 -> 1 | I36: =+SUM(I14,I20,I34) -> 2.3895397e+08 | L36: =IFERROR($I36/L$7,0) -> 517961.92 | N36: =IFERROR($I36/N$7,0) -> 192478.54 | P36: =IFERROR($I36/P$7,0) -> 315.31633 | R36: =IFERROR($I36/R$7,0) -> 557.37255
E38: ='Executive Summary'!E58 -> 0.615 | G38: =I38/$I$36 -> 0.65 | I38: =Debt -> 1.5532008e+08 | L38: =IFERROR($I38/L$7,0) -> 336675.25 | N38: =IFERROR($I38/N$7,0) -> 125111.05 | P38: =IFERROR($I38/P$7,0) -> 204.95562 | R38: =IFERROR($I38/R$7,0) -> 362.29215
E39: Total Equity | G39: =I39/$I$36 -> 0.35 | I39: =Equity -> 83633890 | L39: =IFERROR($I39/L$7,0) -> 181286.67 | N39: =IFERROR($I39/N$7,0) -> 67367.49 | P39: =IFERROR($I39/P$7,0) -> 110.36072 | R39: =IFERROR($I39/R$7,0) -> 195.08039
D224: =+D210-D221 -> 0

Sheet Cash Flow
A1: ='Executive Summary'!$E$5 & " CASH FLOW" -> VERVE Chapel Hill CASH FLOW
A2: CASH FLOW | E2: Per Bed | F2: 1 | G2: =+F2+1 -> 2 | H2: =+G2+1 -> 3 | I2: =+H2+1 -> 4 | J2: =+I2+1 -> 5 | K2: =+J2+1 -> 6 | L2: =+K2+1 -> 7 | M2: =+L2+1 -> 8 | N2: =+M2+1 -> 9 | O2: =+N2+1 -> 10 | Q2: Untrended | S2: Trending | U2: Stabilized Year (Year 2)
A3: EFFECTIVE GROSS REVENUE | Q3: Current Year | U3: Expense Ratios
B4: Gross Potential Rent | E4: =G4/Beds -> 21409.457 | F4: =Assumptions!V60 -> 25804792 | G4: =Assumptions!H60 -> 26578935 | H4: =G4*(1+$S4) -> 27376303 | I4: =H4*(1+$S4) -> 28197592 | J4: =I4*(1+$S4) -> 29043520 | K4: =J4*(1+$S4) -> 29914826 | L4: =K4*(1+$S4) -> 30812271 | M4: =L4*(1+$S4) -> 31736639 | N4: =M4*(1+$S4) -> 32688738 | O4: =N4*(1+$S4) -> 33669400 | Q4: =Assumptions!H60/((1+Assumptions!$D$17)*(1+Assumptions!$D$18)*(1+Assumptions!$D$19)*(1+'Cash Flow'!$S4)) -> 23615040 | S4: =Assumptions!$G60 -> 0.03 | U4: =G36/G17 -> 0.2790831
B5: General Vacancy Loss | E5: =G5/Beds -> -1070.4728 | F5: =Assumptions!V61 -> -5160958.3 | G5: =Assumptions!H61 -> -1328946.8 | H5: =-H4*$S5 -> -1368815.2 | I5: =-I4*$S5 -> -1409879.6 | J5: =-J4*$S5 -> -1452176 | K5: =-K4*$S5 -> -1495741.3 | L5: =-L4*$S5 -> -1540613.5 | M5: =-M4*$S5 -> -1586831.9 | N5: =-N4*$S5 -> -1634436.9 | O5: =-O4*$S5 -> -1683470 | Q5: =-Q4*$S5 -> -1180752 | S5: =Assumptions!$G61 -> 0.05 | U5: Controllable Expenses Per Bed
B6: Collection/ Bad Debt Expense | E6: =G6/Beds -> -152.54238 | F6: =Assumptions!V62 -> -154828.75 | G6: =Assumptions!H62 -> -189374.91 | H6: =-SUM(H4:H5)*$S6 -> -195056.16 | I6: =-SUM(I4:I5)*$S6 -> -200907.85 | J6: =-SUM(J4:J5)*$S6 -> -206935.08 | K6: =-SUM(K4:K5)*$S6 -> -213143.13 | L6: =-SUM(L4:L5)*$S6 -> -219537.43 | M6: =-SUM(M4:M5)*$S6 -> -226123.55 | N6: =-SUM(N4:N5)*$S6 -> -232907.26 | O6: =-SUM(O4:O5)*$S6 -> -239894.48 | Q6: =-SUM(Q4:Q5)*$S6 -> -168257.16 | S6: 0.0075 | U6: =SUM(E20:E25) -> 1887.3545
B7: Parking Revenue | E7: =G7/Beds -> 1188.0121 | F7: =Assumptions!V68 -> 1145527.6 | G7: =Assumptions!H68 -> 1474866.7 | H7: =G7*(1+$S7) -> 1519112.7 | I7: =H7*(1+$S7) -> 1564686.1 | J7: =I7*(1+$S7) -> 1611626.7 | K7: =J7*(1+$S7) -> 1659975.5 | L7: =K7*(1+$S7) -> 1709774.8 | M7: =L7*(1+$S7) -> 1761068 | N7: =M7*(1+$S7) -> 1813900.1 | O7: =N7*(1+$S7) -> 1868317.1 | Q7: =+Assumptions!H68/((1+Assumptions!$D$17)*(1+Assumptions!$D$18)*(1+Assumptions!$D$19)*(1+'Cash Flow'!$S7)) -> 1310400 | S7: =Assumptions!$G68 -> 0.03
B8: Other Income | E8: =G8/Beds -> 488.31338 | F8: =+Assumptions!V84+Assumptions!V86+Assumptions!V106 -> 460127.29 | G8: =+Assumptions!H84+Assumptions!H86+Assumptions!H106 -> 606220.41 | H8: =G8*(1+$S8) -> 624407.02 | I8: =H8*(1+$S8) -> 643139.23 | J8: =I8*(1+$S8) -> 662433.41 | K8: =J8*(1+$S8) -> 682306.41 | L8: =K8*(1+$S8) -> 702775.6 | M8: =L8*(1+$S8) -> 723858.87 | N8: =M8*(1+$S8) -> 745574.64 | O8: =N8*(1+$S8) -> 767941.88 | Q8: =+(Assumptions!H84+Assumptions!H86+Assumptions!H106)/((1+Assumptions!$D$17)*(1+Assumptions!$D$18)*(1+Assumptions!$D$19)*(1+'Cash Flow'!$S8)) -> 538618.98 | S8: =Assumptions!$G84 -> 0.03 | U8: Net Utility Expense Per Bed
B9: Utility Income | E9: =G9/Beds -> 510.97176 | F9: =Assumptions!V80 -> 494638.37 | G9: =Assumptions!H80 -> 634349.82 | H9: =G9*(1+$S9) -> 653380.32 | I9: =H9*(1+$S9) -> 672981.73 | J9: =I9*(1+$S9) -> 693171.18 | K9: =J9*(1+$S9) -> 713966.31 | L9: =K9*(1+$S9) -> 735385.3 | M9: =L9*(1+$S9) -> 757446.86 | N9: =M9*(1+$S9) -> 780170.27 | O9: =N9*(1+$S9) -> 803575.38 | Q9: =+Assumptions!H80/((1+Assumptions!$D$17)*(1+Assumptions!$D$18)*(1+Assumptions!$D$19)*(1+'Cash Flow'!$S9)) -> 563611.6 | S9: =Assumptions!$G80 -> 0.03 | U9: =E27-E9 -> 619.33264
B10: Effective Gross Residential Revenue | E10: =G10/Beds -> 22373.739 | F10: =SUM(F4:F9) -> 22589298 | G10: =SUM(G4:G9) -> 27776051 | H10: =SUM(H4:H9) -> 28609332 | I10: =SUM(I4:I9) -> 29467612 | J10: =SUM(J4:J9) -> 30351640 | K10: =SUM(K4:K9) -> 31262190 | L10: =SUM(L4:L9) -> 32200055 | M10: =SUM(M4:M9) -> 33166057 | ... O10: =SUM(O4:O9) -> 35185870 | Q10: =SUM(Q4:Q9) -> 24678661
B12: Commercial Rent | E12: =G12/Beds -> 52.916582 | F12: =Assumptions!V114 -> 47835.217 | G12: =Assumptions!H114 -> 65693.698 | H12: =+G12 -> 65693.698 | I12: =+H12 -> 65693.698 | J12: =+I12 -> 65693.698 | K12: =+J12 -> 65693.698 | L12: =+K12 -> 65693.698 | M12: =+L12 -> 65693.698 | N12: =+M12 -> 65693.698 | O12: =+N12 -> 65693.698 | Q12: =Assumptions!M45 -> 58368 | S12: =Assumptions!G114 -> 0.03
B13: Commercial Vacancy Loss | E13: =G13/Beds -> -5.2916582 | F13: =-F12*$S13 -> -4783.5217 | G13: =-G12*$S13 -> -6569.3698 | H13: =-H12*$S13 -> -6569.3698 | I13: =-I12*$S13 -> -6569.3698 | J13: =-J12*$S13 -> -6569.3698 | K13: =-K12*$S13 -> -6569.3698 | L13: =-L12*$S13 -> -6569.3698 | M13: =-M12*$S13 -> -6569.3698 | ... O13: =-O12*$S13 -> -6569.3698 | Q13: =-Q12*$S13 -> -5836.8 | S13: =Assumptions!G115 -> 0.1
B14: Commercial Parking | E14: =G14/Beds -> 0 | F14: =Assumptions!V118 -> 0 | G14: =Assumptions!H118 -> 0 | H14: =+G14 -> 0 | I14: =+H14 -> 0 | J14: =+I14 -> 0 | K14: =+J14 -> 0 | L14: =+K14 -> 0 | M14: =+L14 -> 0 | N14: =+M14 -> 0 | O14: =+N14 -> 0 | Q14: =Assumptions!H118 -> 0 | S14: =Assumptions!G118 -> 0.03
B15: CAM Reimbursement | E15: =G15/Beds -> 4.9954179 | F15: =Assumptions!V119 -> 4651.2 | G15: =G34*$S15 -> 6201.6 | H15: =H34*$S15 -> 6356.64 | I15: =I34*$S15 -> 6515.556 | J15: =J34*$S15 -> 6678.4449 | K15: =K34*$S15 -> 6845.406 | L15: =L34*$S15 -> 7016.5412 | M15: =M34*$S15 -> 7191.9547 | N15: =N34*$S15 -> 7371.7536 | O15: =O34*$S15 -> 7556.0474 | Q15: =Q34*$S15 -> 6201.6 | S15: =Assumptions!G119 -> 0.85
B16: Effective Gross Commercial Revenue | E16: =G16/Beds -> 52.620341 | F16: =SUM(F12:F15) -> 47702.895 | G16: =SUM(G12:G15) -> 65325.928 | H16: =SUM(H12:H15) -> 65480.968 | I16: =SUM(I12:I15) -> 65639.884 | J16: =SUM(J12:J15) -> 65802.773 | K16: =SUM(K12:K15) -> 65969.734 | L16: =SUM(L12:L15) -> 66140.87 | M16: =SUM(M12:M15) -> 66316.283 | ... O16: =SUM(O12:O15) -> 66680.376 | Q16: =SUM(Q12:Q15) -> 58732.8
A17: TOTAL EFFECTIVE GROSS REVENUE | E17: =G17/Beds -> 22426.359 | F17: =SUM(F10,F16) -> 22637001 | G17: =SUM(G10,G16) -> 27841377 | H17: =SUM(H10,H16) -> 28674813 | I17: =SUM(I10,I16) -> 29533252 | J17: =SUM(J10,J16) -> 30417443 | K17: =SUM(K10,K16) -> 31328159 | L17: =SUM(L10,L16) -> 32266196 | M17: =SUM(M10,M16) -> 33232373 | ... O17: =SUM(O10,O16) -> 35252550 | Q17: =SUM(Q10,Q16) -> 24737394
U18: Untrended Year
A19: CONTROLLABLE OPERATING EXPENSES | U19: Expense Ratios
B20: =Assumptions!C155 -> General & Administrative | E20: =G20/Beds -> 265.03651 | F20: =Assumptions!V155 -> 321006.46 | G20: =Assumptions!H155 -> 329031.62 | H20: =G20*(1+$S20) -> 337257.41 | I20: =H20*(1+$S20) -> 345688.85 | J20: =I20*(1+$S20) -> 354331.07 | K20: =J20*(1+$S20) -> 363189.35 | L20: =K20*(1+$S20) -> 372269.08 | M20: =L20*(1+$S20) -> 381575.81 | N20: =M20*(1+$S20) -> 391115.2 | O20: =N20*(1+$S20) -> 400893.08 | Q20: =+Assumptions!H155/(1+S20)^(Assumptions!$D$16+1) -> 298086.41 | S20: =Assumptions!G155 -> 0.025 | U20: =$Q$36/$Q$17 -> 0.2843451
B21: =Assumptions!C191 -> Payroll | E21: =G21/Beds -> 845.41029 | F21: =Assumptions!V191 -> 1023942.6 | G21: =Assumptions!H191 -> 1049541.1 | H21: =G21*(1+$S21) -> 1075779.7 | I21: =H21*(1+$S21) -> 1102674.1 | J21: =I21*(1+$S21) -> 1130241 | K21: =J21*(1+$S21) -> 1158497 | L21: =K21*(1+$S21) -> 1187459.4 | M21: =L21*(1+$S21) -> 1217145.9 | N21: =M21*(1+$S21) -> 1247574.6 | O21: =N21*(1+$S21) -> 1278763.9 | Q21: =+Assumptions!H191/(1+S21)^(Assumptions!$D$16+1) -> 950832.46 | S21: =Assumptions!G191 -> 0.025 | U21: Controllable Expenses Per Bed
B22: =Assumptions!C171 -> Leasing and Marketing | E22: =G22/Beds -> 182.70311 | F22: =Assumptions!V171 -> 221286.03 | G22: =Assumptions!H171 -> 226818.18 | H22: =G22*(1+$S22) -> 232488.64 | I22: =H22*(1+$S22) -> 238300.85 | J22: =I22*(1+$S22) -> 244258.38 | K22: =J22*(1+$S22) -> 250364.83 | L22: =K22*(1+$S22) -> 256623.96 | M22: =L22*(1+$S22) -> 263039.55 | N22: =M22*(1+$S22) -> 269615.54 | O22: =N22*(1+$S22) -> 276355.93 | Q22: =+Assumptions!H171/(1+S22)^(Assumptions!$D$16+1) -> 205486.08 | S22: =Assumptions!G171 -> 0.025 | U22: =SUM($Q$20:$Q$25)/Beds -> 1709.85
B23: =Assumptions!C213 -> Maintenance and Repairs | E23: =G23/Beds -> 86.715541 | F23: =Assumptions!V213 -> 105027.98 | G23: =Assumptions!H213 -> 107653.68 | H23: =G23*(1+$S23) -> 110345.02 | I23: =H23*(1+$S23) -> 113103.64 | J23: =I23*(1+$S23) -> 115931.23 | K23: =J23*(1+$S23) -> 118829.52 | L23: =K23*(1+$S23) -> 121800.25 | M23: =L23*(1+$S23) -> 124845.26 | N23: =M23*(1+$S23) -> 127966.39 | O23: =N23*(1+$S23) -> 131165.55 | Q23: =+Assumptions!H213/(1+S23)^(Assumptions!$D$16+1) -> 97528.917 | S23: =Assumptions!G213 -> 0.025
B24: =Assumptions!C233 -> Contract Services | E24: =G24/Beds -> 358.73919 | F24: =Assumptions!V233 -> 434497.1 | G24: =Assumptions!H233 -> 445359.53 | H24: =G24*(1+$S24) -> 456493.52 | I24: =H24*(1+$S24) -> 467905.86 | J24: =I24*(1+$S24) -> 479603.5 | K24: =J24*(1+$S24) -> 491593.59 | L24: =K24*(1+$S24) -> 503883.43 | M24: =L24*(1+$S24) -> 516480.52 | N24: =M24*(1+$S24) -> 529392.53 | O24: =N24*(1+$S24) -> 542627.34 | Q24: =+Assumptions!H233/(1+S24)^(Assumptions!$D$16+1) -> 403473.75 | S24: =Assumptions!G233 -> 0.025 | U24: Net Utility Expense Per Bed
B25: =Assumptions!C243 -> Turnover | E25: =G25/Beds -> 148.74983 | F25: =Assumptions!V243 -> 180162.55 | G25: =Assumptions!H243 -> 184666.62 | H25: =G25*(1+$S25) -> 189283.28 | I25: =H25*(1+$S25) -> 194015.36 | J25: =I25*(1+$S25) -> 198865.75 | K25: =J25*(1+$S25) -> 203837.39 | L25: =K25*(1+$S25) -> 208933.33 | M25: =L25*(1+$S25) -> 214156.66 | N25: =M25*(1+$S25) -> 219510.58 | O25: =N25*(1+$S25) -> 224998.34 | Q25: =+Assumptions!H243/(1+S25)^(Assumptions!$D$16+1) -> 167298.84 | S25: =Assumptions!G243 -> 0.025 | U25: =($Q$27-$Q$9)/Beds -> 570.00821
A26: NON-CONTROLLABLE OPERATING EXPENSES
B27: =Assumptions!C255 -> Utilities | E27: =G27/Beds -> 1130.3044 | F27: =Assumptions!V255 -> 1095016.8 | G27: =Assumptions!H255 -> 1403225.1 | H27: =G27*(1+$S27) -> 1438305.7 | I27: =H27*(1+$S27) -> 1474263.4 | J27: =I27*(1+$S27) -> 1511120 | K27: =J27*(1+$S27) -> 1548898 | L27: =K27*(1+$S27) -> 1587620.4 | M27: =L27*(1+$S27) -> 1627310.9 | N27: =M27*(1+$S27) -> 1667993.7 | O27: =N27*(1+$S27) -> 1709693.5 | Q27: =+Assumptions!H255/(1+S27)^(Assumptions!$D$16+1) -> 1271252.7 | S27: =Assumptions!G255 -> 0.025
B28: =Assumptions!C128 -> Ground Lease | E28: =G28/Beds -> 189.2936 | F28: =Assumptions!V128 -> 235000 | G28: =+F28 -> 235000 | H28: =+G28 -> 235000 | I28: =+H28 -> 235000 | J28: =+I28 -> 235000 | K28: =J28*(1+S28*5) -> 258500 | L28: =+K28 -> 258500 | M28: =+L28 -> 258500 | N28: =+M28 -> 258500 | O28: =+N28 -> 258500 | Q28: =+Assumptions!H128/(1+S28)^(Assumptions!$D$16+1) -> 221445.75 | S28: =Assumptions!G128 -> 0.02
B29: =Assumptions!C129 -> Property Taxes | E29: =G29/Beds -> 1986.8632 | F29: =Assumptions!V129 -> 2406445.5 | G29: =Assumptions!H129 -> 2466606.6 | H29: =G29*(1+$S29) -> 2528271.8 | I29: =H29*(1+$S29) -> 2591478.6 | J29: =I29*(1+$S29) -> 2656265.6 | K29: =J29*(1+$S29) -> 2722672.2 | L29: =K29*(1+$S29) -> 2790739 | M29: =L29*(1+$S29) -> 2860507.5 | N29: =M29*(1+$S29) -> 2932020.2 | O29: =N29*(1+$S29) -> 3005320.7 | Q29: =+Assumptions!H129/(1+S29)^(Assumptions!$D$16+1) -> 2234623.9 | S29: =Assumptions!G129 -> 0.025
B30: =Assumptions!C130 -> Tax Abatement | E30: =G30/Beds -> 0 | F30: =+'Sale Proceeds'!D20 -> 0 | G30: =+'Sale Proceeds'!E20 -> 0 | H30: =+'Sale Proceeds'!F20 -> 0 | I30: =+'Sale Proceeds'!G20 -> 0 | J30: =+'Sale Proceeds'!H20 -> 0 | K30: =+'Sale Proceeds'!I20 -> 0 | L30: =+'Sale Proceeds'!J20 -> 0 | M30: =+'Sale Proceeds'!K20 -> 0 | ... O30: =+'Sale Proceeds'!M20 -> 0 | Q30: =IF(F30<0,-Q29*'Sale Proceeds'!D15,0) -> 0
B31: =Assumptions!C131 -> Insurance | E31: =G31/Beds -> 386.33451 | F31: =Assumptions!V131 -> 467919.96 | G31: =Assumptions!H131 -> 479617.96 | H31: =G31*(1+$S31) -> 491608.41 | I31: =H31*(1+$S31) -> 503898.62 | J31: =I31*(1+$S31) -> 516496.08 | K31: =J31*(1+$S31) -> 529408.48 | L31: =K31*(1+$S31) -> 542643.7 | M31: =L31*(1+$S31) -> 556209.79 | N31: =M31*(1+$S31) -> 570115.03 | O31: =N31*(1+$S31) -> 584367.91 | Q31: =+Assumptions!H131/(1+S31)^(Assumptions!$D$16+1) -> 434510.2 | S31: =Assumptions!G131 -> 0.025
B32: =Assumptions!C257 -> Management Fees | D32: =Assumptions!D257 -> 0.03 | E32: =G32/Beds -> 672.79078 | F32: =Assumptions!V257 -> 679110.02 | G32: =G17*$S$32 -> 835241.3 | H32: =H17*$S$32 -> 860244.39 | I32: =I17*$S$32 -> 885997.56 | J32: =J17*$S$32 -> 912523.3 | K32: =K17*$S$32 -> 939844.78 | L32: =L17*$S$32 -> 967985.89 | M32: =M17*$S$32 -> 996971.2 | N32: =N17*$S$32 -> 1026826 | O32: =O17*$S$32 -> 1057576.5 | Q32: =Q17*$S$32 -> 742121.82 | S32: =Assumptions!D257 -> 0.03
B34: Total Commercial Operating Expenses | E34: =G34/Beds -> 5.8769622 | F34: =Assumptions!V270 -> 7296 | G34: =Assumptions!H270 -> 7296 | H34: =G34*(1+$S34) -> 7478.4 | I34: =H34*(1+$S34) -> 7665.36 | J34: =I34*(1+$S34) -> 7856.994 | K34: =J34*(1+$S34) -> 8053.4188 | L34: =K34*(1+$S34) -> 8254.7543 | M34: =L34*(1+$S34) -> 8461.1232 | N34: =M34*(1+$S34) -> 8672.6513 | O34: =N34*(1+$S34) -> 8889.4675 | Q34: =Assumptions!H270 -> 7296 | S34: =Assumptions!G265 -> 0.025
A36: TOTAL OPERATING EXPENSES | E36: =G36/Beds -> 6258.8179 | F36: =SUM(F20:F35) -> 7176711 | G36: =SUM(G20:G35) -> 7770057.7 | H36: =SUM(H20:H35) -> 7962556.3 | I36: =SUM(I20:I35) -> 8159992.2 | J36: =SUM(J20:J35) -> 8362492.8 | K36: =SUM(K20:K35) -> 8593688.5 | L36: =SUM(L20:L35) -> 8806713.2 | M36: =SUM(M20:M35) -> 9025204.2 | ... O36: =SUM(O20:O35) -> 9479152.3 | Q36: =SUM(Q20:Q35) -> 7033956.8
A38: NET OPERATING INCOME | E38: =G38/Beds -> 16167.541 | F38: =F17-F36 -> 15460290 | G38: =G17-G36 -> 20071319 | H38: =H17-H36 -> 20712257 | I38: =I17-I36 -> 21373260 | J38: =J17-J36 -> 22054950 | K38: =K17-K36 -> 22734471 | L38: =L17-L36 -> 23459483 | M38: =M17-M36 -> 24207169 | ... O38: =O17-O36 -> 25773398 | Q38: =Q17-Q36 -> 17703437
A40: CAPITAL
B41: Commercial Capital Reserves | E41: =G41/Beds -> 0 | F41: =Assumptions!V277 -> 0 | G41: =Assumptions!H277 -> 0 | H41: =G41*(1+$S41) -> 0 | I41: =H41*(1+$S41) -> 0 | J41: =I41*(1+$S41) -> 0 | K41: =J41*(1+$S41) -> 0 | L41: =K41*(1+$S41) -> 0 | M41: =L41*(1+$S41) -> 0 | N41: =M41*(1+$S41) -> 0 | O41: =N41*(1+$S41) -> 0 | Q41: =+Assumptions!H277/(1+S41)^(Assumptions!$D$16+1) -> 0 | R41: =+Q41*(1+S41)^4 -> 0 | S41: =Assumptions!G277 -> 0.03
B42: Residential Capital Reserve | E42: =G42/Beds -> 140.6886 | F42: =Assumptions!V281 -> 169571.79 | G42: =Assumptions!H281 -> 174658.95 | H42: =G42*(1+$S42) -> 179898.72 | I42: =H42*(1+$S42) -> 185295.68 | J42: =I42*(1+$S42) -> 190854.55 | K42: =J42*(1+$S42) -> 196580.18 | L42: =K42*(1+$S42) -> 202477.59 | M42: =L42*(1+$S42) -> 208551.92 | N42: =M42*(1+$S42) -> 214808.48 | O42: =N42*(1+$S42) -> 221252.73 | Q42: =+Assumptions!H281/(1+S42)^(Assumptions!$D$16+1) -> 155182.21 | R42: =+Q42*(1+S42)^4 -> 174658.95 | S42: =Assumptions!G281 -> 0.03
A43: TOTAL CAPITAL | E43: =G43/Beds -> 140.6886 | F43: =SUM(F41:F42) -> 169571.79 | G43: =SUM(G41:G42) -> 174658.95 | H43: =SUM(H41:H42) -> 179898.72 | I43: =SUM(I41:I42) -> 185295.68 | J43: =SUM(J41:J42) -> 190854.55 | K43: =SUM(K41:K42) -> 196580.18 | L43: =SUM(L41:L42) -> 202477.59 | M43: =SUM(M41:M42) -> 208551.92 | ... O43: =SUM(O41:O42) -> 221252.73 | Q43: =SUM(Q41:Q42) -> 155182.21
A45: NET OPERATING INCOME (LESS RESERVES) | E45: =G45/Beds -> 16026.853 | F45: =F38-F43 -> 15290718 | G45: =G38-G43 -> 19896660 | H45: =H38-H43 -> 20532358 | I45: =I38-I43 -> 21187964 | J45: =J38-J43 -> 21864096 | K45: =K38-K43 -> 22537891 | L45: =L38-L43 -> 23257005 | M45: =M38-M43 -> 23998617 | ... O45: =O38-O43 -> 25552145 | Q45: =Q38-Q43 -> 17548255
C46: RETURN ON COST | F46: =(F$45+F$30)/'Development Summary'!$I$36 -> 0.063990223 | G46: =(G$45+G$30)/'Development Summary'!$I$36 -> 0.083265659 | H46: =(H$45+H$30)/'Development Summary'!$I$36 -> 0.085925997 | I46: =(I$45+I$30)/'Development Summary'!$I$36 -> 0.088669646 | J46: =(J$45+J$30)/'Development Summary'!$I$36 -> 0.091499195 | K46: =(K$45+K$30)/'Development Summary'!$I$36 -> 0.094318963 | L46: =(L$45+L$30)/'Development Summary'!$I$36 -> 0.097328391 | M46: =(M$45+M$30)/'Development Summary'!$I$36 -> 0.10043197 | ... O46: =(O$45+O$30)/'Development Summary'!$I$36 -> 0.10693334 | Q46: =(Q$45+Q$30)/('Development Summary'!$I$36-7311231) -> 0.075755688
...

Sheet Assumptions
B1: ='Executive Summary'!$E$5&" ASSUMPTIONS" -> VERVE Chapel Hill ASSUMPTIONS
C4: ASSUMPTIONS | F4: UNIT MIX
C5: Residential Assumptions | G5: Unit Name | H5: Unit Type | I5: Avg Unit SF | J5: Avg Bed SF | K5: Beds Per Unit | L5: Total # of Units | M5: Total # of Beds | N5: % of Total Units | O5: % of Total Beds | P5: Current Year Per Bed Input | Q5: Current Year Rent PSF | R5: Year 1 Rent/Bed | S5: Year 1 Rent/Unit | T5: Year 1 Rent PSF | U5: Total SF
C6: Units | D6: =+$L$37 -> 461.33501 | F6: =NOT(ISBLANK(K6))*OFFSET(F6,-1,0)+1 -> 1 | G6: S1 | H6: STUDIO | I6: 414 | J6: =IFERROR((I6/K6),"") -> 414 | K6: =IFERROR(IF(H6="Studio",1,LEFT(H6,1)),"") -> 1 | L6: 14.669417 | M6: =IFERROR(L6*K6,"") -> 14.669417 | N6: =IFERROR($L6/$L$22,"") -> 0.031797753 | O6: =IFERROR($M6/$M$22,"") -> 0.011816284 | P6: 1925 | Q6: =+IFERROR((P6*K6)/I6,"") -> 4.6497585 | R6: =IFERROR(P6*(1+$D$17)*(1+$D$18)*(1+$D$19),"") -> 2103.4995 | S6: =IFERROR(P6*K6*(1+$D$17)*(1+$D$18)*(1+$D$19),"") -> 2103.4995 | T6: =IFERROR(S6/I6,0) -> 5.0809166 | U6: =IFERROR(I6*L6,"") -> 6073.1385
C7: Beds | D7: =+$M$37 -> 1241.4577 | F7: =NOT(ISBLANK(K7))*OFFSET(F7,-1,0)+1 -> 2 | G7: S1 AFF | H7: STUDIO | I7: 414 | J7: =IFERROR((I7/K7),"") -> 414 | K7: =IFERROR(IF(H7="Studio",1,LEFT(H7,1)),"") -> 1 | L7: 13.84005 | M7: =IFERROR(L7*K7,"") -> 13.84005 | N7: =IFERROR($L7/$L$22,"") -> 0.03 | O7: =IFERROR($M7/$M$22,"") -> 0.011148225 | P7: 1215 | Q7: =+IFERROR((P7*K7)/I7,"") -> 2.9347826 | R7: =IFERROR(P7*(1+$D$17)*(1+$D$18)*(1+$D$19),"") -> 1327.6633 | S7: =IFERROR(P7*K7*(1+$D$17)*(1+$D$18)*(1+$D$19),"") -> 1327.6633 | T7: =IFERROR(S7/I7,0) -> 3.2069162 | U7: =IFERROR(I7*L7,"") -> 5729.7809
C8: Residential Vacancy (YR 1) | D8: 0.2 | F8: =NOT(ISBLANK(K8))*OFFSET(F8,-1,0)+1 -> 3 | G8: A1 | H8: 1BR/1BA | I8: 500 | J8: =IFERROR((I8/K8),"") -> 500 | K8: =IFERROR(IF(H8="Studio",1,LEFT(H8,1)),"") -> 1 | L8: 56.137733 | M8: =IFERROR(L8*K8,"") -> 56.137733 | N8: =IFERROR($L8/$L$22,"") -> 0.12168539 | O8: =IFERROR($M8/$M$22,"") -> 0.045219207 | P8: 2075 | Q8: =+IFERROR((P8*K8)/I8,"") -> 4.15 | R8: =IFERROR(P8*(1+$D$17)*(1+$D$18)*(1+$D$19),"") -> 2267.4085 | S8: =IFERROR(P8*K8*(1+$D$17)*(1+$D$18)*(1+$D$19),"") -> 2267.4085 | T8: =IFERROR(S8/I8,0) -> 4.5348171 | U8: =IFERROR(I8*L8,"") -> 28068.866
C9: Residential Vacancy (YR 2) | D9: 0.05 | F9: =NOT(ISBLANK(K9))*OFFSET(F9,-1,0)+1 -> 4 | G9: A1 AFF | H9: 1BR/1BA | I9: 500 | J9: =IFERROR((I9/K9),"") -> 500 | K9: =IFERROR(IF(H9="Studio",1,LEFT(H9,1)),"") -> 1 | L9: 13.84005 | M9: =IFERROR(L9*K9,"") -> 13.84005 | N9: =IFERROR($L9/$L$22,"") -> 0.03 | O9: =IFERROR($M9/$M$22,"") -> 0.011148225 | P9: 1301 | Q9: =+IFERROR((P9*K9)/I9,"") -> 2.602 | R9: =IFERROR(P9*(1+$D$17)*(1+$D$18)*(1+$D$19),"") -> 1421.6378 | S9: =IFERROR(P9*K9*(1+$D$17)*(1+$D$18)*(1+$D$19),"") -> 1421.6378 | T9: =IFERROR(S9/I9,0) -> 2.8432757 | U9: =IFERROR(I9*L9,"") -> 6920.0252
C10: Max Leased Units (YR 1) | D10: =ROUNDDOWN($D$6*(1-$D$8),0) -> 369 | F10: =NOT(ISBLANK(K10))*OFFSET(F10,-1,0)+1 -> 5 | G10: B1 | H10: 2BR/2BA | I10: 750 | J10: =IFERROR((I10/K10),"") -> 375 | K10: =IFERROR(IF(H10="Studio",1,LEFT(H10,1)),"") -> 2 | L10: 102.78959 | M10: =IFERROR(L10*K10,"") -> 205.57918 | N10: =IFERROR($L10/$L$22,"") -> 0.22280899 | O10: =IFERROR($M10/$M$22,"") -> 0.16559499 | P10: 1675 | Q10: =+IFERROR((P10*K10)/I10,"") -> 4.4666667 | R10: =IFERROR(P10*(1+$D$17)*(1+$D$18)*(1+$D$19),"") -> 1830.3177 | S10: =IFERROR(P10*K10*(1+$D$17)*(1+$D$18)*(1+$D$19),"") -> 3660.6354 | T10: =IFERROR(S10/I10,0) -> 4.8808473 | U10: =IFERROR(I10*L10,"") -> 77092.191
C11: Max Leased Units (YR 2) | D11: =ROUNDDOWN($D$6*(1-$D$9),0) -> 438 | F11: 6 | G11: B1 AFF | H11: 2BR/2BA | I11: 750 | J11: =IFERROR((I11/K11),"") -> 375 | K11: =IFERROR(IF(H11="Studio",1,LEFT(H11,1)),"") -> 2 | L11: 13.84005 | M11: =IFERROR(L11*K11,"") -> 27.680101 | N11: =IFERROR($L11/$L$22,"") -> 0.03 | O11: =IFERROR($M11/$M$22,"") -> 0.022296451 | P11: 846 | Q11: =+IFERROR((P11*K11)/I11,"") -> 2.256 | R11: =IFERROR(P11*(1+$D$17)*(1+$D$18)*(1+$D$19),"") -> 924.44704 | S11: =IFERROR(P11*K11*(1+$D$17)*(1+$D$18)*(1+$D$19),"") -> 1848.8941 | T11: =IFERROR(S11/I11,0) -> 2.4651921 | U11: =IFERROR(I11*L11,"") -> 10380.038
C12: Max Leased Beds (YR 1) | D12: =ROUNDDOWN($D$7*(1-$D$8),0) -> 993 | F12: 7 | G12: C1 | H12: 3BR/3BA | I12: 1050 | J12: =IFERROR((I12/K12),"") -> 350 | K12: =IFERROR(IF(H12="Studio",1,LEFT(H12,1)),"") -> 3 | L12: 70.547972 | M12: =IFERROR(L12*K12,"") -> 211.64392 | N12: =IFERROR($L12/$L$22,"") -> 0.15292135 | O12: =IFERROR($M12/$M$22,"") -> 0.17048017 | P12: 1600 | Q12: =+IFERROR((P12*K12)/I12,"") -> 4.5714286 | R12: =IFERROR(P12*(1+$D$17)*(1+$D$18)*(1+$D$19),"") -> 1748.3632 | S12: =IFERROR(P12*K12*(1+$D$17)*(1+$D$18)*(1+$D$19),"") -> 5245.0896 | T12: =IFERROR(S12/I12,0) -> 4.9953234 | U12: =IFERROR(I12*L12,"") -> 74075.371
C13: Max Leased Beds (YR 2) | D13: =ROUNDDOWN($D$7*(1-$D$9),0) -> 1179 | F13: 8 | G13: C1 AFF | H13: 3BR/3BA | I13: 1050 | J13: =IFERROR((I13/K13),"") -> 350 | K13: =IFERROR(IF(H13="Studio",1,LEFT(H13,1)),"") -> 3 | L13: 4.6133501 | M13: =IFERROR(L13*K13,"") -> 13.84005 | N13: =IFERROR($L13/$L$22,"") -> 0.01 | O13: =IFERROR($M13/$M$22,"") -> 0.011148225 | P13: 651.33333 | Q13: =+IFERROR((P13*K13)/I13,"") -> 1.8609524 | R13: =IFERROR(P13*(1+$D$17)*(1+$D$18)*(1+$D$19),"") -> 711.72952 | S13: =IFERROR(P13*K13*(1+$D$17)*(1+$D$18)*(1+$D$19),"") -> 2135.1886 | T13: =IFERROR(S13/I13,0) -> 2.0335129 | U13: =IFERROR(I13*L13,"") -> 4844.0176
C14: Leasing Start | D14: =Development!$N$9 -> 32 | F14: 9 | G14: D1 | H14: 4BR/4BA | I14: 1260 | J14: =IFERROR((I14/K14),"") -> 315 | K14: =IFERROR(IF(H14="Studio",1,LEFT(H14,1)),"") -> 4 | L14: 171.0568 | M14: =IFERROR(L14*K14,"") -> 684.22721 | N14: =IFERROR($L14/$L$22,"") -> 0.37078652 | O14: =IFERROR($M14/$M$22,"") -> 0.55114823 | P14: 1550 | Q14: =+IFERROR((P14*K14)/I14,"") -> 4.9206349 | R14: =IFERROR(P14*(1+$D$17)*(1+$D$18)*(1+$D$19),"") -> 1693.7269 | S14: =IFERROR(P14*K14*(1+$D$17)*(1+$D$18)*(1+$D$19),"") -> 6774.9074 | T14: =IFERROR(S14/I14,0) -> 5.3769106 | U14: =IFERROR(I14*L14,"") -> 215531.57
C15: Residential Lease-Up Period (Year 1) | D15: 1
C16: Years Trending | D16: =+COUNTIF(D17:D19,">0%") -> 3
C17: Rent Trending - Year 1 | D17: 0.03
C18: Rent Trending - Year 2 | D18: 0.03
C19: Rent Trending - Year 3 | D19: 0.03
C20: OpEx Trending - All Years | D20: 0.025
C21: Residential Parking Spaces | D21: 624
C22: Residential Parking Rent / Space | D22: 175 | I22: =SUMPRODUCT(I$6:I$21,$L$6:$L$21)/$L22 -> 929.29213 | J22: =SUMPRODUCT(J$6:J$21,$M$6:$M$21)/$M22 -> 345.33194 | K22: =M22/L22 -> 2.6910112 | L22: =SUM(L6:L21) -> 461.33501 | M22: =SUM(M6:M21) -> 1241.4577 | N22: =$L22/$L$22 -> 1 | O22: =$L22/$L$22 -> 1 | P22: =SUMPRODUCT(P$6:P$21,$O$6:$O$21) -> 1575.1688 | Q22: =SUMPRODUCT(Q6:Q21,O6:O21) -> 4.6063697 | R22: =SUMPRODUCT(R$6:R$21,$O$6:$O$21) -> 1721.2294 | S22: =SUMPRODUCT(S$6:S$21,$L$6:$L$21)/$L22 -> 4631.8478 | T22: =IFERROR(S22/I22,0) -> 4.9842752 | U22: =+SUM(U6:U21) -> 428715 | AC22: Total Parking | AD22: 629
C23: Move-in Fee Concessions | D23: 0.3 | F23: UNIT MIX SUMMARY | AC23: Guest Spaces | AD23: 5
C24: Pet Rent | D24: =10%*(1-D9) -> 0.095 | AC24: Commercial Spaces | AD24: 0
C25: Non-Refundable Security Deposit | D25: 350 | F25: =OFFSET(F25,-1,0)+1 -> 1 | H25: STUDIO | I25: =SUMPRODUCT(I$6:I$14,$L$6:$L$14,--($H$6:$H$14=$H25))/$L25 -> 414 | J25: =SUMPRODUCT(J$6:J$14,$L$6:$L$14,--($H$6:$H$14=$H25))/$L25 -> 414 | K25: =SUMIF($H$6:$H$15,$H25,M$6:M$15)/SUMIF($H$6:$H$15,$H25,$L$6:$L$15) -> 1 | L25: =SUMIF($H$6:$H$15,H25,L$6:L$15) -> 28.509467 | M25: =SUMIF($H$6:$H$15,H25,M$6:M$15) -> 28.509467 | N25: =$L25/$L$37 -> 0.061797753 | O25: =$M25/$M$37 -> 0.022964509 | P25: =SUMPRODUCT(P$6:P$15,$L$6:$L$15,--($H$6:$H$15=H25))/$L25 -> 1580.3273 | Q25: =IFERROR((P25*K25)/I25,0) -> 3.8172156 | R25: {=SUMPRODUCT(R$6:R$15,$L$6:$L$15,--($H$6:$H$15=H25))/$L25} -> 1726.8663 | S25: =SUMPRODUCT(S$6:S$15,$L$6:$L$15,--($H$6:$H$15=H25))/$L25 -> 1726.8663 | T25: =IFERROR(S25/I25,0) -> 4.1711746 | U25: =+I25*L25 -> 11802.919 | AC25: Other Spaces
C26: Storage Assumptions | D26: 0 | F26: =OFFSET(F26,-1,0)+1 -> 2 | H26: 1BR/1BA | I26: =SUMPRODUCT(I$6:I$14,$L$6:$L$14,--($H$6:$H$14=$H26))/$L26 -> 500 | J26: =SUMPRODUCT(J$6:J$14,$L$6:$L$14,--($H$6:$H$14=$H26))/$L26 -> 500 | K26: =SUMIF($H$6:$H$15,$H26,M$6:M$15)/SUMIF($H$6:$H$15,$H26,$L$6:$L$15) -> 1 | L26: =SUMIF($H$6:$H$15,H26,L$6:L$15) -> 69.977783 | M26: =SUMIF($H$6:$H$15,H26,M$6:M$15) -> 69.977783 | N26: =$L26/$L$37 -> 0.15168539 | O26: =$M26/$M$37 -> 0.056367432 | P26: =SUMPRODUCT(P$6:P$15,$L$6:$L$15,--($H$6:$H$15=H26))/$L26 -> 1921.92 | Q26: =IFERROR((P26*K26)/I26,0) -> 3.84384 | R26: {=SUMPRODUCT(R$6:R$15,$L$6:$L$15,--($H$6:$H$15=H26))/$L26} -> 2100.1339 | S26: =SUMPRODUCT(S$6:S$15,$L$6:$L$15,--($H$6:$H$15=H26))/$L26 -> 2100.1339 | T26: =IFERROR(S26/I26,0) -> 4.2002678 | U26: =+I26*L26 -> 34988.892 | AC26: Residential Spaces | AD26: =AD22-AD23-AD24-AD25 -> 624
C27: Half Height Lockers | D27: 35 | F27: =OFFSET(F27,-1,0)+1 -> 3 | H27: 2BR/2BA | I27: =SUMPRODUCT(I$6:I$14,$L$6:$L$14,--($H$6:$H$14=$H27))/$L27 -> 750 | J27: =SUMPRODUCT(J$6:J$14,$L$6:$L$14,--($H$6:$H$14=$H27))/$L27 -> 375 | K27: =SUMIF($H$6:$H$15,$H27,M$6:M$15)/SUMIF($H$6:$H$15,$H27,$L$6:$L$15) -> 2 | L27: =SUMIF($H$6:$H$15,H27,L$6:L$15) -> 116.62964 | M27: =SUMIF($H$6:$H$15,H27,M$6:M$15) -> 233.25928 | N27: =$L27/$L$37 -> 0.25280899 | O27: =$M27/$M$37 -> 0.18789144 | P27: =SUMPRODUCT(P$6:P$15,$L$6:$L$15,--($H$6:$H$15=H27))/$L27 -> 1576.6253 | Q27: =IFERROR((P27*K27)/I27,0) -> 4.2043342 | R27: {=SUMPRODUCT(R$6:R$15,$L$6:$L$15,--($H$6:$H$15=H27))/$L27} -> 1722.8211 | S27: =SUMPRODUCT(S$6:S$15,$L$6:$L$15,--($H$6:$H$15=H27))/$L27 -> 3445.6421 | T27: =IFERROR(S27/I27,0) -> 4.5941895 | U27: =+I27*L27 -> 87472.229
C28: Full Height Lockers | D28: 75 | F28: =OFFSET(F28,-1,0)+1 -> 4 | H28: 3BR/3BA | I28: =SUMPRODUCT(I$6:I$14,$L$6:$L$14,--($H$6:$H$14=$H28))/$L28 -> 1050 | J28: =SUMPRODUCT(J$6:J$14,$L$6:$L$14,--($H$6:$H$14=$H28))/$L28 -> 350 | K28: =SUMIF($H$6:$H$15,$H28,M$6:M$15)/SUMIF($H$6:$H$15,$H28,$L$6:$L$15) -> 3 | L28: =SUMIF($H$6:$H$15,H28,L$6:L$15) -> 75.161322 | M28: =SUMIF($H$6:$H$15,H28,M$6:M$15) -> 225.48397 | N28: =$L28/$L$37 -> 0.16292135 | O28: =$M28/$M$37 -> 0.18162839 | P28: =SUMPRODUCT(P$6:P$15,$L$6:$L$15,--($H$6:$H$15=H28))/$L28 -> 1541.7715 | Q28: =IFERROR((P28*K28)/I28,0) -> 4.4050614 | R28: {=SUMPRODUCT(R$6:R$15,$L$6:$L$15,--($H$6:$H$15=H28))/$L28} -> 1684.7353 | S28: =SUMPRODUCT(S$6:S$15,$L$6:$L$15,--($H$6:$H$15=H28))/$L28 -> 5054.206 | T28: =IFERROR(S28/I28,0) -> 4.8135295 | U28: =+I28*L28 -> 78919.389
C29: Annual Renewal | D29: 0.3 | F29: 5 | H29: 4BR/4BA | I29: {=SUMPRODUCT(I$6:I$15,$L$6:$L$15,--($H$6:$H$15=$H29))/$L29} -> 1260 | J29: {=SUMPRODUCT(J$6:J$15,$L$6:$L$15,--($H$6:$H$15=$H29))/$L29} -> 315 | K29: =SUMIF($H$6:$H$15,$H29,M$6:M$15)/SUMIF($H$6:$H$15,$H29,$L$6:$L$15) -> 4 | L29: =SUMIF($H$6:$H$15,H29,L$6:L$15) -> 171.0568 | M29: =SUMIF($H$6:$H$15,H29,M$6:M$15) -> 684.22721 | N29: =$L29/$L$37 -> 0.37078652 | O29: =$M29/$M$37 -> 0.55114823 | P29: =SUMPRODUCT(P$6:P$15,$L$6:$L$15,--($H$6:$H$15=H29))/$L29 -> 1550 | Q29: =IFERROR((P29*K29)/I29,0) -> 4.9206349 | R29: {=SUMPRODUCT(R$6:R$15,$L$6:$L$15,--($H$6:$H$15=H29))/$L29} -> 1693.7269 | S29: =SUMPRODUCT(S$6:S$15,$L$6:$L$15,--($H$6:$H$15=H29))/$L29 -> 6774.9074 | T29: =IFERROR(S29/I29,0) -> 5.3769106 | U29: =+I29*L29 -> 215531.57
C30: Premium Units | D30: 0.1
C31: (Per Month - Per Bed) | D31: 100
F34: =IF((ISBLANK(H34))," ",OFFSET(F34,-1,0)+1)
C35: Commercial Assumptions | F35: =IF((ISBLANK(H35))," ",OFFSET(F35,-1,0)+1)
C36: Commercial Leasing Start | D36: 4 | F36: =IF((ISBLANK(H36))," ",OFFSET(F36,-1,0)+1) | I36: {=IFERROR(SUMPRODUCT(I$6:I$20,$L$6:$L$20,--($H$6:$H$20=$H36))/$L36,"")} | J36: {=IFERROR(SUMPRODUCT(J$6:J$20,$L$6:$L$20,--($H$6:$H$20=$H36))/$L36,"")} | K36: =IFERROR(SUMIF($H$6:$H$21,$H36,M$6:M$21)/SUMIF($H$6:$H$21,$H36,$L$6:$L$21),"") | L36: =IF(ISBLANK(H36)," ",(IFERROR(SUMIF($H$6:$H$21,H36,L$6:L$21),""))) | M36: =IF(ISBLANK(H36)," ",(IFERROR(SUMIF($H$6:$H$21,H36,M$6:M$21),""))) | N36: =IFERROR($L36/$L$37,"") | O36: =IFERROR($M36/$M$37,"") | P36: {=IFERROR(SUMPRODUCT(P$6:P$21,$L$6:$L$21,--($H$6:$H$21=H36))/$L36,"")} | Q36: =IF(ISBLANK(H36)," ",(IFERROR((P36*K36)/I36,0))) | R36: {=IFERROR(SUMPRODUCT(R$6:R$21,$L$6:$L$21,--($H$6:$H$21=H36))/$L36,"")} | S36: {=IFERROR(SUMPRODUCT(S$6:S$21,$L$6:$L$21,--($H$6:$H$21=H36))/$L36,"")} | T36: =IF(ISBLANK(H36)," ",IFERROR(S36/I36,0)) | U36: =IFERROR(I36*L36,"")
C37: Commercial Vacancy | D37: 0.1 | F37: =MAX(F23:F36) -> 5 | I37: =SUMPRODUCT(I$24:I$36,$L$24:$L$36)/$L37 -> 929.29213 | J37: =SUMPRODUCT(J$24:J$36,$M$24:$M$36)/$M37 -> 345.33194 | K37: =M37/L37 -> 2.6910112 | L37: =IFERROR(SUM(L$24:L$36),"") -> 461.33501 | M37: =IFERROR(SUM(M$24:M$36),"") -> 1241.4577 | N37: =$L37/$L$37 -> 1 | O37: =$L37/$L$37 -> 1 | P37: =IFERROR(SUMPRODUCT(P$24:P$36,$O$24:$O$36),"") -> 1575.1688 | Q37: =IFERROR(SUMPRODUCT(Q24:Q36,O24:O36),"") -> 4.6063697 | R37: =IFERROR(SUMPRODUCT(R$24:R$36,$O$24:$O$36),"") -> 1721.2294 | S37: =IFERROR(SUMPRODUCT(S$24:S$36,$L$24:$L$36)/$L37,0) -> 4631.8478 | T37: =IFERROR(S37/I37,0) -> 4.9842752 | U37: =+SUM(U24:U36) -> 428715
C38: CAM Reimbursement | D38: 0.85
C39: Commercial Parking Spaces | D39: =+$X$24 -> 0
C40: Commercial Parking Rent / Space | D40: 0 | F40: COMMERCIAL UNITS
G41: Suite | H41: Tenant Name | I41: Total SF | J41: Mix | K41: Duration (Years) | L41: Rent/ SF/ YR | M41: Current Rent/Yr | N41: Year 1 Rent/Yr | O41: TI (PSF) | P41: LC (%)
C42: Utility Assumptions
C43: Water & Sewer Recapture | D43: 0 | F43: =OFFSET(F43,-1,0)+1 -> 1 | G43: Retail | H43: TBD | I43: 1824 | J43: =IFERROR(I43/$I$45,0) -> 1 | K43: 10 | L43: 32 | M43: =L43*I43 -> 58368 | N43: =M43*(1+$D$17)*(1+$D$18)*(1+$D$19) -> 63780.29 | O43: 75 | P43: =6%+3% -> 0.09
C44: Electric Recapture | D44: 0.95
...

Sheet Development
D1: ='Executive Summary'!$E$5& " DEVELOPMENT" -> VERVE Chapel Hill DEVELOPMENT | T1: Detailed | AI1: Calcs | AJ1: 0 | AK1: 1 | AL1: =+AK1+1 -> 2 | AM1: =+AL1+1 -> 3 | AN1: =+AM1+1 -> 4 | AO1: =+AN1+1 -> 5 | AP1: =+AO1+1 -> 6 | AQ1: =+AP1+1 -> 7 | AR1: =+AQ1+1 -> 8 | AS1: =+AR1+1 -> 9 | ... EZ1: =+EY1+1 -> 120
AJ2: 0 | AK2: 1 | AL2: 1 | AM2: 1 | AN2: 1 | AO2: 1 | AP2: 1 | AQ2: 1 | AR2: 1 | AS2: 1 | AT2: 1 | AU2: 1 | AV2: 1 | AW2: =+AK2+1 -> 2 | AX2: =+AL2+1 -> 2 | AY2: =+AM2+1 -> 2 | AZ2: =+AN2+1 -> 2 | BA2: =+AO2+1 -> 2 | BB2: =+AP2+1 -> 2 | BC2: =+AQ2+1 -> 2 | BD2: =+AR2+1 -> 2 | ... EZ2: =+EN2+1 -> 10
AJ3: =StartDate-1 -> 46752 | AK3: =EOMONTH(StartDate,0) -> 46783 | AL3: =EOMONTH(AK3,1) -> 46812 | AM3: =EOMONTH(AL3,1) -> 46843 | AN3: =EOMONTH(AM3,1) -> 46873 | AO3: =EOMONTH(AN3,1) -> 46904 | AP3: =EOMONTH(AO3,1) -> 46934 | AQ3: =EOMONTH(AP3,1) -> 46965 | AR3: =EOMONTH(AQ3,1) -> 46996 | AS3: =EOMONTH(AR3,1) -> 47026 | ... EZ3: =EOMONTH(EY3,1) -> 50405
D5: FACTOR CALCULATION METRICS | J5: PROJECT TIMING
M6: Start Dates | N6: Start Month | O6: Duration Months | P6: End Month
D7: Area Measures | J7: Land Acquisition Date | M7: =+StartDate -> 46753 | N7: 1 | O7: 1 | P7: =MAX(0,N7+O7-1) -> 1
E8: Amount | H8: 1 | J8: Construction Phase | M8: =DATE(YEAR(M7),MONTH(M7)+O7,DAY(M7)) -> 46784 | N8: =P7+1 -> 2 | O8: 30 | P8: =MAX(0,N8+O8-1) -> 31
E9: Total Units | H9: =+Units -> 461.33501 | J9: Lease-up Phase (Delivery Year) | M9: =DATE(YEAR(M8),MONTH(M8)+O8,DAY(M8)) -> 47696 | N9: =+P8+1 -> 32 | O9: 12 | P9: =MAX(0,N9+O9-1) -> 43
E10: Total Beds | H10: =Assumptions!$M$22 -> 1241.4577 | J10: Lease-up Phase (Year 2) | M10: =DATE(YEAR(M9),MONTH(M9)+O9,DAY(M9)) -> 48061 | N10: =+P9+1 -> 44 | O10: 12 | P10: =MAX(0,N10+O10-1) -> 55
E11: Gross Res SF | H11: 502832 | J11: Operations Phase | M11: =DATE(YEAR(M10),MONTH(M10)+O10,DAY(M10)) -> 48427 | N11: =P10+1 -> 56 | O11: =120-N11+1 -> 65 | P11: =MAX(0,N11+O11-1) -> 120
E12: Amenity and Leasing SF | H12: 20325 | J12: Last Month of Construction Loan | M12: =+M10-1 -> 48060 | N12: =+N10 -> 44 | P12: =+N11-1 -> 55
E13: Commercial SF | H13: 1824
E14: Parking SF | H14: 232842
E15: Total Gross SF | H15: =SUM(H11:H14) -> 757823
E16: Total Net SF | H16: =+Assumptions!U22 -> 428715
E17: Total FAR SF | H17: 0 | J17: DISPLAY PARAMETERS
E18: Land SF | H18: =+H285 -> 338897 | J18: Amounts display per this Metric in Summary | P18: Total Units
E19: Land Acres | H19: =H18/43560 -> 7.7800046 | J19: Building Type | P19: Mid-Rise
D20: % of Costs
E21: % of Land Costs | H21: =IFERROR(G40,0) -> 25587500
E22: % of Construction Costs | H22: =IFERROR(G81,0) -> 1.6084708e+08 | I22: Excludes Site Work & HC Contingency
E23: % of Hard Costs | H23: =IFERROR(SUM(G69,G81),0) -> 1.6162208e+08 | I23: Excludes HC Contingency
E24: % of Soft Costs | H24: =IFERROR(G246-G215-G231-G238-G244,0) -> 21291596 | I24: Excludes SC Contingency, Dev Fee, CM Fee, and Const. Interest
E25: % of Const. Financing Costs | H25: =IFERROR(G225,0) -> 9958874.8
E26: % of Total Project Costs | H26: =IFERROR(G256-G238,0) -> 2.2976343e+08 | I26: Excludes Developer Fee
E27: % of Total Hard & Soft Costs | H27: =IFERROR(SUM(H23:H24),0) -> 1.8291367e+08 | I27: See above Exclusions
E28: TBD 1 | H28: 0
D29: % of Loan
E30: % of Construction Loan | H30: =IFERROR($G$267,0) -> 1.5532008e+08
U33: Duration | V33: Distribution | W33: Midpoint Begin After | X33: Midpoint End After | Y33: Midpoint PeriodPercentage | Z33: 2 (balanced), or 3 (backload) | AA33: Ratio Peak /Trough | AB33: m | AC33: r | AD33: i | AE33: a1 | AF33: b1 | AG33: a2 | AH33: b2
D34: ACQUISITION COSTS | G34: Total Budget | H34: Unit Price | I34: Factor | J34: Units | K34: Cost/Bed | L34: Cost/GSF | M34: Cost/NSF | N34: Start Date | O34: Start Month | P34: Months | Q34: End Month | R34: Distribution | S34: Comments / Description | U34: DISTRIBUTION CALCULATIONS
D35: 1 | E35: Land Costs
E37: =IF(ISBLANK(F37)," ",OFFSET(E37,-1,0)+1) -> 1 | F37: Purchase Price - Magma Equities | G37: =H37*J37 -> 25000000 | H37: 25000000 | I37: Amount | J37: =INDEX(FACTOR_VALUES,MATCH(I37,FACTOR_NAMES,0),1) -> 1 | K37: =+$G37/Beds -> 20137.617 | L37: =+$G37/$H$15 -> 32.989234 | M37: =+$G37/$H$16 -> 58.313798 | N37: =EOMONTH($M$7,O37-2)+1 -> 46753 | O37: =$N$7 -> 1 | P37: 1 | Q37: =O37-1+P37 -> 1 | R37: Flat | U37: =+P37 -> 1 | V37: =+R37 -> Flat | W37: =INT(U37*AB37)+O37-1 -> 0 | X37: =(U37-INT(U37*(1-AB37)))+O37-1 -> 1 | Y37: =(AB37-(W37-O37+1)/U37)*(AF37+AE37*(2*(W37-O37+1)/U37+(AB37-(W37-O37+1)/U37)))+((X37-O37+1)/U37-AB37)*(AH37+AG37*(2*AB37+((X37-O37+1)/U37-AB37))) -> 1 | Z37: =IF(V37="curve-front",1,IF(V37="curve-end",3,2)) -> 2 | AA37: =IF(OR(V37="curve-front",V37="curve-mid",V37="curve-end"),2.5,1) -> 1 | AB37: =Z37/4 -> 0.5 | AC37: =AA37-1 -> 0 | AD37: =1/U37 -> 1 | AE37: =AC37/(AB37*(2+AC37)) -> 0 | AF37: =2/(2+AC37) -> 1 | AG37: =-AC37/(2+AC37)/(1-AB37) -> 0 | AH37: =2*(1-AB37+AC37)/(2+AC37)/(1-AB37) -> 1 | AJ37: =IF(AND(AJ$1>=$O37,AJ$1<=$Q37),$G37*IF(AJ$1<=$W37,$AD37*($AF37+$AE37*(2*INT((AJ$1-$O37))/$U37+$AD37)),IF(AJ$1<=$X37,$Y37,IF(AJ$1<=$U37+$O37,$AD37*($AH37+$AG37*(2*INT((AJ$1-$O37))/$U37+$AD37)),0))),0) -> 0 | AK37: =IF(AND(AK$1>=$O37,AK$1<=$Q37),$G37*IF(AK$1<=$W37,$AD37*($AF37+$AE37*(2*INT((AK$1-$O37))/$U37+$AD37)),IF(AK$1<=$X37,$Y37,IF(AK$1<=$U37+$O37,$AD37*($AH37+$AG37*(2*INT((AK$1-$O37))/$U37+$AD37)),0))),0) -> 25000000 | AL37: =IF(AND(AL$1>=$O37,AL$1<=$Q37),$G37*IF(AL$1<=$W37,$AD37*($AF37+$AE37*(2*INT((AL$1-$O37))/$U37+$AD37)),IF(AL$1<=$X37,$Y37,IF(AL$1<=$U37+$O37,$AD37*($AH37+$AG37*(2*INT((AL$1-$O37))/$U37+$AD37)),0))),0) -> 0 | AM37: =IF(AND(AM$1>=$O37,AM$1<=$Q37),$G37*IF(AM$1<=$W37,$AD37*($AF37+$AE37*(2*INT((AM$1-$O37))/$U37+$AD37)),IF(AM$1<=$X37,$Y37,IF(AM$1<=$U37+$O37,$AD37*($AH37+$AG37*(2*INT((AM$1-$O37))/$U37+$AD37)),0))),0) -> 0 | AN37: =IF(AND(AN$1>=$O37,AN$1<=$Q37),$G37*IF(AN$1<=$W37,$AD37*($AF37+$AE37*(2*INT((AN$1-$O37))/$U37+$AD37)),IF(AN$1<=$X37,$Y37,IF(AN$1<=$U37+$O37,$AD37*($AH37+$AG37*(2*INT((AN$1-$O37))/$U37+$AD37)),0))),0) -> 0 | AO37: =IF(AND(AO$1>=$O37,AO$1<=$Q37),$G37*IF(AO$1<=$W37,$AD37*($AF37+$AE37*(2*INT((AO$1-$O37))/$U37+$AD37)),IF(AO$1<=$X37,$Y37,IF(AO$1<=$U37+$O37,$AD37*($AH37+$AG37*(2*INT((AO$1-$O37))/$U37+$AD37)),0))),0) -> 0 | AP37: =IF(AND(AP$1>=$O37,AP$1<=$Q37),$G37*IF(AP$1<=$W37,$AD37*($AF37+$AE37*(2*INT((AP$1-$O37))/$U37+$AD37)),IF(AP$1<=$X37,$Y37,IF(AP$1<=$U37+$O37,$AD37*($AH37+$AG37*(2*INT((AP$1-$O37))/$U37+$AD37)),0))),0) -> 0 | AQ37: =IF(AND(AQ$1>=$O37,AQ$1<=$Q37),$G37*IF(AQ$1<=$W37,$AD37*($AF37+$AE37*(2*INT((AQ$1-$O37))/$U37+$AD37)),IF(AQ$1<=$X37,$Y37,IF(AQ$1<=$U37+$O37,$AD37*($AH37+$AG37*(2*INT((AQ$1-$O37))/$U37+$AD37)),0))),0) -> 0 | ... EZ37: =IF(AND(EZ$1>=$O37,EZ$1<=$Q37),$G37*IF(EZ$1<=$W37,$AD37*($AF37+$AE37*(2*INT((EZ$1-$O37))/$U37+$AD37)),IF(EZ$1<=$X37,$Y37,IF(EZ$1<=$U37+$O37,$AD37*($AH37+$AG37*(2*INT((EZ$1-$O37))/$U37+$AD37)),0))),0) -> 0
